Workbook

Sheet Summary
A1: Town of Berlin, MD — Council Check Run Analysis
A2: Approved disbursements, Jan 1, 2025 – Jun 8, 2026 (21 council meetings)
A3: Source: berlinmd.gov council-meetings check run reports · Prepared 2026-06-22
A5: AP Vendor Payments | C5: Utility Refunds | E5: Total Disbursed | G5: Vendors / Line Items
A6: ='By Meeting'!B23 -> 11638444 | C6: ='By Meeting'!D23 -> 28550.47 | E6: ='By Meeting'!E23 -> 11666994 | G6: =COUNTA('By Vendor'!A2:A446)&" / "&'By Meeting'!C23 -> 445 / 1811
A9: Spending by Category | E9: Top 15 Vendors
A10: Category | B10: Total Paid | C10: % of AP | E10: Vendor | F10: Total Paid | G10: # Pmts
A11: Other / General | B11: ='By Category'!B2 -> 2373254.1 | C11: ='By Category'!D2 -> 0.20391507 | E11: NEXGRID | F11: ='By Vendor'!C2 -> 711670.11 | G11: ='By Vendor'!D2 -> 8
A12: Payroll, Taxes & Benefits | B12: ='By Category'!B3 -> 2045940.5 | C12: ='By Category'!D3 -> 0.17579159 | E12: ATLANTIC MACHINERY, INC | F12: ='By Vendor'!C3 -> 632266.99 | G12: ='By Vendor'!D3 -> 7
A13: Vehicles, Fleet & Equipment | B13: ='By Category'!B4 -> 1952538.2 | C13: ='By Category'!D4 -> 0.16776626 | E13: BENEFITMALL | F13: ='By Vendor'!C4 -> 620063.52 | G13: ='By Vendor'!D4 -> 6
A14: Electric/Water Utility Materials | B14: ='By Category'!B5 -> 1113691.4 | C14: ='By Category'!D5 -> 0.095690744 | E14: CRC BENEFITS | F14: ='By Vendor'!C5 -> 571604.82 | G14: ='By Vendor'!D5 -> 6
A15: Professional Services (Legal/Eng/Audit) | B15: ='By Category'!B6 -> 1041950.9 | C15: ='By Category'!D6 -> 0.089526655 | E15: BERLIN FIRE COMPANY EMERGENCY MEDICAL SERVICES INC | F15: ='By Vendor'!C6 -> 499000 | G15: ='By Vendor'!D6 -> 1
A16: Public Safety (Fire/EMS/Police) | B16: ='By Category'!B7 -> 938738.19 | C16: ='By Category'!D7 -> 0.080658394 | E16: HERTRICH FLEET SERVIICES INC | F16: ='By Vendor'!C7 -> 441931 | G16: ='By Vendor'!D7 -> 4
A17: Construction & Infrastructure | B17: ='By Category'!B8 -> 890926.07 | C17: ='By Category'!D8 -> 0.076550275 | E17: BERLIN FIRE CO | F17: ='By Vendor'!C8 -> 430775.24 | G17: ='By Vendor'!D8 -> 5
A18: Interfund / Town Transfers | B18: ='By Category'!B9 -> 360773.18 | C18: ='By Category'!D9 -> 0.030998404 | E18: TOWN OF BERLIN | F18: ='By Vendor'!C9 -> 360773.18 | G18: ='By Vendor'!D9 -> 12
A19: Technology & Software | B19: ='By Category'!B10 -> 283222.7 | C19: ='By Category'!D10 -> 0.0243351 | E19: EAST COAST CONTRACTING | F19: ='By Vendor'!C10 -> 310748.14 | G19: ='By Vendor'!D10 -> 4
A20: Waste & Disposal | B20: ='By Category'!B11 -> 190346.2 | C20: ='By Category'!D11 -> 0.016354953 | E20: DAVIS, BOWEN & FRIEDEL | F20: ='By Vendor'!C11 -> 280908.4 | G20: ='By Vendor'!D11 -> 14
A21: Debt Service & State Loans | B21: ='By Category'!B12 -> 190186.44 | C21: ='By Category'!D12 -> 0.016341226 | E21: HALEY ARCHITECTURE | F21: ='By Vendor'!C12 -> 280514.85 | G21: ='By Vendor'!D12 -> 14
A22: Utilities & Telecom | B22: ='By Category'!B13 -> 183985.91 | C22: ='By Category'!D13 -> 0.015808463 | E22: ATT:DATA CONTROLL DIV-PAYROLL MARYLAND STATE RETIREMENT | F22: ='By Vendor'!C13 -> 268434 | G22: ='By Vendor'!D13 -> 1
... A25: Health Services | B25: ='By Category'!B16 -> 4811 | C25: ='By Category'!D16 -> 0.00041337142 | E25: THE PETE STORE | F25: ='By Vendor'!C16 -> 227323.76 | G25: ='By Vendor'!D16 -> 5
A26: TOTAL | B26: =SUM(B11:B25) -> 11638444
A28: Scope & Method
A29: • Covers all 21 Check Run Reports posted on berlinmd.gov for council meetings from 01/27/2025 through 06/08/2026.
A30: • "AP Vendor Payments" = vendor accounts-payable checks approved at each meeting (the substantive operating expenses).
A31: • "Utility Refunds" = customer utility-billing refund checks, listed separately on the Utility Refunds tab.
A32: • Every meeting's extracted vendor total was reconciled to the PDF's stated packet totals (see 'By Meeting' → Reconciles?).
A33: Important caveats
A34: • The 08/11/2025 report posted on the site is a duplicate of the 07/28/2025 report (identical $2,178,400.96, same packets dated 07/03–07/29). It is EXCLUDED to avoid double-counting.
A35: • No separate check run reports were posted for some meetings (e.g., June 2025, parts of spring 2026); only posted reports are included.
A36: • Credit-card (Bank of Ocean City) statements bundled in some PDFs are shown on the 'Credit Cards (memo)' tab and are EXCLUDED from totals, since those purchases are typically paid via a separate AP check (avoids double counting).
A37: • Categories are assigned heuristically by vendor-name keywords; 'Other / General' holds vendors that didn't match a rule. Re-categorize on the 'AP Line Items' tab if needed — all rollups are live formulas.
A38: • A vendor paid in multiple packets/meetings appears as multiple line items; the 'By Vendor' tab sums them.

Sheet By Meeting
A1: Meeting Date | B1: AP Vendor Payments | C1: # Vendor Lines | D1: Utility Refunds | E1: Combined Disbursed | F1: Stated Total (PDF) | G1: Reconciles?
A2: 01.27.2025 | B2: =SUMIF('AP Line Items'!A:A,A2,'AP Line Items'!E:E) -> 586548.05 | C2: =COUNTIF('AP Line Items'!A:A,A2) -> 101 | D2: =SUMIF('Utility Refunds'!A:A,A2,'Utility Refunds'!D:D) -> 1610.97 | E2: =B2+D2 -> 588159.02 | F2: 586548.05 | G2: =IF(ROUND(B2-F2,2)=0,"OK","CHECK") -> OK
A3: 02.10.2025 | B3: =SUMIF('AP Line Items'!A:A,A3,'AP Line Items'!E:E) -> 467011.99 | C3: =COUNTIF('AP Line Items'!A:A,A3) -> 103 | D3: =SUMIF('Utility Refunds'!A:A,A3,'Utility Refunds'!D:D) -> 0 | E3: =B3+D3 -> 467011.99 | F3: — | G3: n/a
A4: 02.24.2025 | B4: =SUMIF('AP Line Items'!A:A,A4,'AP Line Items'!E:E) -> 378057.21 | C4: =COUNTIF('AP Line Items'!A:A,A4) -> 68 | D4: =SUMIF('Utility Refunds'!A:A,A4,'Utility Refunds'!D:D) -> 136.54 | E4: =B4+D4 -> 378193.75 | F4: 378057.21 | G4: =IF(ROUND(B4-F4,2)=0,"OK","CHECK") -> OK
A5: 03.10.2025 | B5: =SUMIF('AP Line Items'!A:A,A5,'AP Line Items'!E:E) -> 95573.55 | C5: =COUNTIF('AP Line Items'!A:A,A5) -> 26 | D5: =SUMIF('Utility Refunds'!A:A,A5,'Utility Refunds'!D:D) -> 2765.96 | E5: =B5+D5 -> 98339.51 | F5: 95573.55 | G5: =IF(ROUND(B5-F5,2)=0,"OK","CHECK") -> OK
A6: 03.24.2025 | B6: =SUMIF('AP Line Items'!A:A,A6,'AP Line Items'!E:E) -> 698880.9 | C6: =COUNTIF('AP Line Items'!A:A,A6) -> 107 | D6: =SUMIF('Utility Refunds'!A:A,A6,'Utility Refunds'!D:D) -> 8222.94 | E6: =B6+D6 -> 707103.84 | F6: — | G6: n/a
A7: 04.14.2025 | B7: =SUMIF('AP Line Items'!A:A,A7,'AP Line Items'!E:E) -> 550852.8 | C7: =COUNTIF('AP Line Items'!A:A,A7) -> 74 | D7: =SUMIF('Utility Refunds'!A:A,A7,'Utility Refunds'!D:D) -> 108.54 | E7: =B7+D7 -> 550961.34 | F7: — | G7: n/a
A8: 04.28.2025 | B8: =SUMIF('AP Line Items'!A:A,A8,'AP Line Items'!E:E) -> 216970.01 | C8: =COUNTIF('AP Line Items'!A:A,A8) -> 65 | D8: =SUMIF('Utility Refunds'!A:A,A8,'Utility Refunds'!D:D) -> 1681.44 | E8: =B8+D8 -> 218651.45 | F8: 216970.01 | G8: =IF(ROUND(B8-F8,2)=0,"OK","CHECK") -> OK
A9: 05.12.2025 | B9: =SUMIF('AP Line Items'!A:A,A9,'AP Line Items'!E:E) -> 682868.17 | C9: =COUNTIF('AP Line Items'!A:A,A9) -> 83 | D9: =SUMIF('Utility Refunds'!A:A,A9,'Utility Refunds'!D:D) -> 1369.75 | E9: =B9+D9 -> 684237.92 | F9: 682868.17 | G9: =IF(ROUND(B9-F9,2)=0,"OK","CHECK") -> OK
A10: 05.27.2025 | B10: =SUMIF('AP Line Items'!A:A,A10,'AP Line Items'!E:E) -> 396675.57 | C10: =COUNTIF('AP Line Items'!A:A,A10) -> 90 | D10: =SUMIF('Utility Refunds'!A:A,A10,'Utility Refunds'!D:D) -> 144.66 | E10: =B10+D10 -> 396820.23 | F10: — | G10: n/a
A11: 07.28.2025 | B11: =SUMIF('AP Line Items'!A:A,A11,'AP Line Items'!E:E) -> 2178401 | C11: =COUNTIF('AP Line Items'!A:A,A11) -> 167 | D11: =SUMIF('Utility Refunds'!A:A,A11,'Utility Refunds'!D:D) -> 455.29 | E11: =B11+D11 -> 2178856.2 | F11: — | G11: n/a
A12: 08.25.2025 | B12: =SUMIF('AP Line Items'!A:A,A12,'AP Line Items'!E:E) -> 486640.82 | C12: =COUNTIF('AP Line Items'!A:A,A12) -> 46 | D12: =SUMIF('Utility Refunds'!A:A,A12,'Utility Refunds'!D:D) -> 0 | E12: =B12+D12 -> 486640.82 | F12: 486640.82 | G12: =IF(ROUND(B12-F12,2)=0,"OK","CHECK") -> OK
A13: 09.08.2025 | B13: =SUMIF('AP Line Items'!A:A,A13,'AP Line Items'!E:E) -> 638168.12 | C13: =COUNTIF('AP Line Items'!A:A,A13) -> 132 | D13: =SUMIF('Utility Refunds'!A:A,A13,'Utility Refunds'!D:D) -> 2529.66 | E13: =B13+D13 -> 640697.78 | F13: — | G13: n/a
A14: 10.14.2025 | B14: =SUMIF('AP Line Items'!A:A,A14,'AP Line Items'!E:E) -> 236815.1 | C14: =COUNTIF('AP Line Items'!A:A,A14) -> 94 | D14: =SUMIF('Utility Refunds'!A:A,A14,'Utility Refunds'!D:D) -> 213.56 | E14: =B14+D14 -> 237028.66 | F14: 236815.1 | G14: =IF(ROUND(B14-F14,2)=0,"OK","CHECK") -> OK
A15: 10.27.2025 | B15: =SUMIF('AP Line Items'!A:A,A15,'AP Line Items'!E:E) -> 680266.07 | C15: =COUNTIF('AP Line Items'!A:A,A15) -> 116 | D15: =SUMIF('Utility Refunds'!A:A,A15,'Utility Refunds'!D:D) -> 32.03 | E15: =B15+D15 -> 680298.1 | F15: — | G15: n/a
A16: 11.10.2025 | B16: =SUMIF('AP Line Items'!A:A,A16,'AP Line Items'!E:E) -> 163323.18 | C16: =COUNTIF('AP Line Items'!A:A,A16) -> 41 | D16: =SUMIF('Utility Refunds'!A:A,A16,'Utility Refunds'!D:D) -> 121.89 | E16: =B16+D16 -> 163445.07 | F16: 163323.18 | G16: =IF(ROUND(B16-F16,2)=0,"OK","CHECK") -> OK
A17: 12.08.2025 | B17: =SUMIF('AP Line Items'!A:A,A17,'AP Line Items'!E:E) -> 1396442.9 | C17: =COUNTIF('AP Line Items'!A:A,A17) -> 114 | D17: =SUMIF('Utility Refunds'!A:A,A17,'Utility Refunds'!D:D) -> 618.62 | E17: =B17+D17 -> 1397061.5 | F17: 1396442.9 | G17: =IF(ROUND(B17-F17,2)=0,"OK","CHECK") -> OK
A18: 01.12.2026 | B18: =SUMIF('AP Line Items'!A:A,A18,'AP Line Items'!E:E) -> 430976.3 | C18: =COUNTIF('AP Line Items'!A:A,A18) -> 77 | D18: =SUMIF('Utility Refunds'!A:A,A18,'Utility Refunds'!D:D) -> 6987.68 | E18: =B18+D18 -> 437963.98 | F18: 430976.3 | G18: =IF(ROUND(B18-F18,2)=0,"OK","CHECK") -> OK
A19: 02.09.2026 | B19: =SUMIF('AP Line Items'!A:A,A19,'AP Line Items'!E:E) -> 82239.04 | C19: =COUNTIF('AP Line Items'!A:A,A19) -> 38 | D19: =SUMIF('Utility Refunds'!A:A,A19,'Utility Refunds'!D:D) -> 455.44 | E19: =B19+D19 -> 82694.48 | F19: 82239.04 | G19: =IF(ROUND(B19-F19,2)=0,"OK","CHECK") -> OK
A20: 02.23.2026 | B20: =SUMIF('AP Line Items'!A:A,A20,'AP Line Items'!E:E) -> 584074.21 | C20: =COUNTIF('AP Line Items'!A:A,A20) -> 127 | D20: =SUMIF('Utility Refunds'!A:A,A20,'Utility Refunds'!D:D) -> 0 | E20: =B20+D20 -> 584074.21 | F20: — | G20: n/a
A21: 03.09.2026 | B21: =SUMIF('AP Line Items'!A:A,A21,'AP Line Items'!E:E) -> 149427.08 | C21: =COUNTIF('AP Line Items'!A:A,A21) -> 48 | D21: =SUMIF('Utility Refunds'!A:A,A21,'Utility Refunds'!D:D) -> 973.56 | E21: =B21+D21 -> 150400.64 | F21: — | G21: n/a
A22: 06.08.2026 | B22: =SUMIF('AP Line Items'!A:A,A22,'AP Line Items'!E:E) -> 538231.83 | C22: =COUNTIF('AP Line Items'!A:A,A22) -> 94 | D22: =SUMIF('Utility Refunds'!A:A,A22,'Utility Refunds'!D:D) -> 121.94 | E22: =B22+D22 -> 538353.77 | F22: — | G22: n/a
A23: GRAND TOTAL | B23: =SUM(B2:B22) -> 11638444 | C23: =SUM(C2:C22) -> 1811 | D23: =SUM(D2:D22) -> 28550.47 | E23: =SUM(E2:E22) -> 11666994

Sheet By Category
A1: Category | B1: Total Paid | C1: # Line Items | D1: % of AP
A2: Other / General | B2: =SUMIF('AP Line Items'!D:D,A2,'AP Line Items'!E:E) -> 2373254.1 | C2: =COUNTIF('AP Line Items'!D:D,A2) -> 905 | D2: =B2/$B$17 -> 0.20391507
A3: Payroll, Taxes & Benefits | B3: =SUMIF('AP Line Items'!D:D,A3,'AP Line Items'!E:E) -> 2045940.5 | C3: =COUNTIF('AP Line Items'!D:D,A3) -> 110 | D3: =B3/$B$17 -> 0.17579159
A4: Vehicles, Fleet & Equipment | B4: =SUMIF('AP Line Items'!D:D,A4,'AP Line Items'!E:E) -> 1952538.2 | C4: =COUNTIF('AP Line Items'!D:D,A4) -> 146 | D4: =B4/$B$17 -> 0.16776626
A5: Electric/Water Utility Materials | B5: =SUMIF('AP Line Items'!D:D,A5,'AP Line Items'!E:E) -> 1113691.4 | C5: =COUNTIF('AP Line Items'!D:D,A5) -> 101 | D5: =B5/$B$17 -> 0.095690744
A6: Professional Services (Legal/Eng/Audit) | B6: =SUMIF('AP Line Items'!D:D,A6,'AP Line Items'!E:E) -> 1041950.9 | C6: =COUNTIF('AP Line Items'!D:D,A6) -> 78 | D6: =B6/$B$17 -> 0.089526655
A7: Public Safety (Fire/EMS/Police) | B7: =SUMIF('AP Line Items'!D:D,A7,'AP Line Items'!E:E) -> 938738.19 | C7: =COUNTIF('AP Line Items'!D:D,A7) -> 11 | D7: =B7/$B$17 -> 0.080658394
A8: Construction & Infrastructure | B8: =SUMIF('AP Line Items'!D:D,A8,'AP Line Items'!E:E) -> 890926.07 | C8: =COUNTIF('AP Line Items'!D:D,A8) -> 43 | D8: =B8/$B$17 -> 0.076550275
A9: Interfund / Town Transfers | B9: =SUMIF('AP Line Items'!D:D,A9,'AP Line Items'!E:E) -> 360773.18 | C9: =COUNTIF('AP Line Items'!D:D,A9) -> 12 | D9: =B9/$B$17 -> 0.030998404
A10: Technology & Software | B10: =SUMIF('AP Line Items'!D:D,A10,'AP Line Items'!E:E) -> 283222.7 | C10: =COUNTIF('AP Line Items'!D:D,A10) -> 87 | D10: =B10/$B$17 -> 0.0243351
A11: Waste & Disposal | B11: =SUMIF('AP Line Items'!D:D,A11,'AP Line Items'!E:E) -> 190346.2 | C11: =COUNTIF('AP Line Items'!D:D,A11) -> 16 | D11: =B11/$B$17 -> 0.016354953
A12: Debt Service & State Loans | B12: =SUMIF('AP Line Items'!D:D,A12,'AP Line Items'!E:E) -> 190186.44 | C12: =COUNTIF('AP Line Items'!D:D,A12) -> 2 | D12: =B12/$B$17 -> 0.016341226
A13: Utilities & Telecom | B13: =SUMIF('AP Line Items'!D:D,A13,'AP Line Items'!E:E) -> 183985.91 | C13: =COUNTIF('AP Line Items'!D:D,A13) -> 125 | D13: =B13/$B$17 -> 0.015808463
... A16: Health Services | B16: =SUMIF('AP Line Items'!D:D,A16,'AP Line Items'!E:E) -> 4811 | C16: =COUNTIF('AP Line Items'!D:D,A16) -> 18 | D16: =B16/$B$17 -> 0.00041337142
A17: TOTAL | B17: =SUM(B2:B16) -> 11638444 | D17: =SUM(D2:D16) -> 1

Sheet By Vendor
A1: Vendor (normalized) | B1: Category | C1: Total Paid | D1: # Payments | E1: % of AP
A2: NEXGRID | B2: Electric/Water Utility Materials | C2: =SUMIF('AP Line Items'!C:C,"NEXGRID",'AP Line Items'!E:E) -> 711670.11 | D2: =COUNTIF('AP Line Items'!C:C,"NEXGRID") -> 8 | E2: =C2/$C$447 -> 0.061148219
A3: ATLANTIC MACHINERY, INC | B3: Vehicles, Fleet & Equipment | C3: =SUMIF('AP Line Items'!C:C,"ATLANTIC MACHINERY",'AP Line Items'!E:E) -> 632266.99 | D3: =COUNTIF('AP Line Items'!C:C,"ATLANTIC MACHINERY") -> 7 | E3: =C3/$C$447 -> 0.054325733
A4: BENEFITMALL | B4: Payroll, Taxes & Benefits | C4: =SUMIF('AP Line Items'!C:C,"BENEFITMALL",'AP Line Items'!E:E) -> 620063.52 | D4: =COUNTIF('AP Line Items'!C:C,"BENEFITMALL") -> 6 | E4: =C4/$C$447 -> 0.053277185
A5: CRC BENEFITS | B5: Payroll, Taxes & Benefits | C5: =SUMIF('AP Line Items'!C:C,"CRC BENEFITS",'AP Line Items'!E:E) -> 571604.82 | D5: =COUNTIF('AP Line Items'!C:C,"CRC BENEFITS") -> 6 | E5: =C5/$C$447 -> 0.049113509
A6: BERLIN FIRE COMPANY EMERGENCY MEDICAL SERVICES INC | B6: Public Safety (Fire/EMS/Police) | C6: =SUMIF('AP Line Items'!C:C,"BERLIN FIRE COMPANY EMERGENCY MEDICAL SERVICES",'AP Line Items'!E:E) -> 499000 | D6: =COUNTIF('AP Line Items'!C:C,"BERLIN FIRE COMPANY EMERGENCY MEDICAL SERVICES") -> 1 | E6: =C6/$C$447 -> 0.042875148
A7: HERTRICH FLEET SERVIICES INC | B7: Vehicles, Fleet & Equipment | C7: =SUMIF('AP Line Items'!C:C,"HERTRICH",'AP Line Items'!E:E) -> 441931 | D7: =COUNTIF('AP Line Items'!C:C,"HERTRICH") -> 4 | E7: =C7/$C$447 -> 0.037971657
A8: BERLIN FIRE CO | B8: Public Safety (Fire/EMS/Police) | C8: =SUMIF('AP Line Items'!C:C,"BERLIN FIRE",'AP Line Items'!E:E) -> 430775.24 | D8: =COUNTIF('AP Line Items'!C:C,"BERLIN FIRE") -> 5 | E8: =C8/$C$447 -> 0.03701313
A9: TOWN OF BERLIN | B9: Interfund / Town Transfers | C9: =SUMIF('AP Line Items'!C:C,"TOWN OF BERLIN",'AP Line Items'!E:E) -> 360773.18 | D9: =COUNTIF('AP Line Items'!C:C,"TOWN OF BERLIN") -> 12 | E9: =C9/$C$447 -> 0.030998404
A10: EAST COAST CONTRACTING | B10: Construction & Infrastructure | C10: =SUMIF('AP Line Items'!C:C,"EAST COAST CONTRACTING",'AP Line Items'!E:E) -> 310748.14 | D10: =COUNTIF('AP Line Items'!C:C,"EAST COAST CONTRACTING") -> 4 | E10: =C10/$C$447 -> 0.026700145
A11: DAVIS, BOWEN & FRIEDEL | B11: Professional Services (Legal/Eng/Audit) | C11: =SUMIF('AP Line Items'!C:C,"DAVIS BOWEN & FRIEDEL",'AP Line Items'!E:E) -> 280908.4 | D11: =COUNTIF('AP Line Items'!C:C,"DAVIS BOWEN & FRIEDEL") -> 14 | E11: =C11/$C$447 -> 0.024136251
A12: HALEY ARCHITECTURE | B12: Professional Services (Legal/Eng/Audit) | C12: =SUMIF('AP Line Items'!C:C,"HALEY ARCHITECTURE",'AP Line Items'!E:E) -> 280514.85 | D12: =COUNTIF('AP Line Items'!C:C,"HALEY ARCHITECTURE") -> 14 | E12: =C12/$C$447 -> 0.024102436
A13: ATT:DATA CONTROLL DIV-PAYROLL MARYLAND STATE RETIREMENT | B13: Payroll, Taxes & Benefits | C13: =SUMIF('AP Line Items'!C:C,"ATT:DATA CONTROLL DIV-PAYROLL MARYLAND STATE RETIREMENT",'AP Line Items'!E:E) -> 268434 | D13: =COUNTIF('AP Line Items'!C:C,"ATT:DATA CONTROLL DIV-PAYROLL MARYLAND STATE RETIREMENT") -> 1 | E13: =C13/$C$447 -> 0.023064424
A14: COMPTROLLER OF MARYLAND | B14: Payroll, Taxes & Benefits | C14: =SUMIF('AP Line Items'!C:C,"COMPTROLLER OF MARYLAND",'AP Line Items'!E:E) -> 267596.34 | D14: =COUNTIF('AP Line Items'!C:C,"COMPTROLLER OF MARYLAND") -> 23 | E14: =C14/$C$447 -> 0.02299245
A15: CUNNINGHAM ASSOCIATES INC | B15: Other / General | C15: =SUMIF('AP Line Items'!C:C,"CUNNINGHAM ASSOCIATES",'AP Line Items'!E:E) -> 266605.91 | D15: =COUNTIF('AP Line Items'!C:C,"CUNNINGHAM ASSOCIATES") -> 2 | E15: =C15/$C$447 -> 0.02290735
A16: THE PETE STORE | B16: Vehicles, Fleet & Equipment | C16: =SUMIF('AP Line Items'!C:C,"THE PETE STORE",'AP Line Items'!E:E) -> 227323.76 | D16: =COUNTIF('AP Line Items'!C:C,"THE PETE STORE") -> 5 | E16: =C16/$C$447 -> 0.019532144
A17: GRAN TURK EQUIPMENT CO | B17: Vehicles, Fleet & Equipment | C17: =SUMIF('AP Line Items'!C:C,"GRAN TURK EQUIPMENT",'AP Line Items'!E:E) -> 205674.47 | D17: =COUNTIF('AP Line Items'!C:C,"GRAN TURK EQUIPMENT") -> 2 | E17: =C17/$C$447 -> 0.017671991
A18: MARYLAND WATER QUALITY FINANCING ADMINISTRATION | B18: Debt Service & State Loans | C18: =SUMIF('AP Line Items'!C:C,"MARYLAND WATER QUALITY FINANCING ADMINISTRATION",'AP Line Items'!E:E) -> 190186.44 | D18: =COUNTIF('AP Line Items'!C:C,"MARYLAND WATER QUALITY FINANCING ADMINISTRATION") -> 2 | E18: =C18/$C$447 -> 0.016341226
A19: CARTER MACHINERY COMPANY INC | B19: Vehicles, Fleet & Equipment | C19: =SUMIF('AP Line Items'!C:C,"CARTER MACHINERY COMPANY",'AP Line Items'!E:E) -> 189254.63 | D19: =COUNTIF('AP Line Items'!C:C,"CARTER MACHINERY COMPANY") -> 13 | E19: =C19/$C$447 -> 0.016261163
A20: WORCESTER COUNTY LANDFILL | B20: Waste & Disposal | C20: =SUMIF('AP Line Items'!C:C,"WORCESTER COUNTY LANDFILL",'AP Line Items'!E:E) -> 186418.7 | D20: =COUNTIF('AP Line Items'!C:C,"WORCESTER COUNTY LANDFILL") -> 14 | E20: =C20/$C$447 -> 0.016017494
A21: HOPKINS CONSTRUCTION INC | B21: Construction & Infrastructure | C21: =SUMIF('AP Line Items'!C:C,"HOPKINS CONSTRUCTION",'AP Line Items'!E:E) -> 169845.97 | D21: =COUNTIF('AP Line Items'!C:C,"HOPKINS CONSTRUCTION") -> 3 | E21: =C21/$C$447 -> 0.014593529
A22: LOCAL GOVERNMENT INSURANCE TRUST | B22: Payroll, Taxes & Benefits | C22: =SUMIF('AP Line Items'!C:C,"LOCAL GOVERNMENT INSURANCE TRUST",'AP Line Items'!E:E) -> 166471 | D22: =COUNTIF('AP Line Items'!C:C,"LOCAL GOVERNMENT INSURANCE TRUST") -> 11 | E22: =C22/$C$447 -> 0.014303545
A23: BOOTH & ASSOCIATES INC | B23: Professional Services (Legal/Eng/Audit) | C23: =SUMIF('AP Line Items'!C:C,"BOOTH & ASSOCIATES",'AP Line Items'!E:E) -> 153336.79 | D23: =COUNTIF('AP Line Items'!C:C,"BOOTH & ASSOCIATES") -> 10 | E23: =C23/$C$447 -> 0.013175025
A24: CATO OIL CO., INC. | B24: Other / General | C24: =SUMIF('AP Line Items'!C:C,"CATO OIL",'AP Line Items'!E:E) -> 142760.07 | D24: =COUNTIF('AP Line Items'!C:C,"CATO OIL") -> 11 | E24: =C24/$C$447 -> 0.012266251
A25: HAWKINS INC | B25: Electric/Water Utility Materials | C25: =SUMIF('AP Line Items'!C:C,"HAWKINS",'AP Line Items'!E:E) -> 138456.42 | D25: =COUNTIF('AP Line Items'!C:C,"HAWKINS") -> 24 | E25: =C25/$C$447 -> 0.011896472
A26: TYLER TECHNOLOGIES INC | B26: Technology & Software | C26: =SUMIF('AP Line Items'!C:C,"TYLER TECHNOLOGIES",'AP Line Items'!E:E) -> 133154.89 | D26: =COUNTIF('AP Line Items'!C:C,"TYLER TECHNOLOGIES") -> 9 | E26: =C26/$C$447 -> 0.011440953
A27: GROUNDWORK SOLUTIONS INC | B27: Construction & Infrastructure | C27: =SUMIF('AP Line Items'!C:C,"GROUNDWORK SOLUTIONS",'AP Line Items'!E:E) -> 116132.48 | D27: =COUNTIF('AP Line Items'!C:C,"GROUNDWORK SOLUTIONS") -> 8 | E27: =C27/$C$447 -> 0.0099783512
A28: NATIONWIDE RETIREMENT SOLUTIONS | B28: Payroll, Taxes & Benefits | C28: =SUMIF('AP Line Items'!C:C,"NATIONWIDE RETIREMENT SOLUTIONS",'AP Line Items'!E:E) -> 112590 | D28: =COUNTIF('AP Line Items'!C:C,"NATIONWIDE RETIREMENT SOLUTIONS") -> 25 | E28: =C28/$C$447 -> 0.0096739737
A29: EA ENGINEERING, SCIENCE AND TECHNOLOGY INC PBC | B29: Professional Services (Legal/Eng/Audit) | C29: =SUMIF('AP Line Items'!C:C,"EA ENGINEERING SCIENCE AND TECHNOLOGY PBC",'AP Line Items'!E:E) -> 99357.07 | D29: =COUNTIF('AP Line Items'!C:C,"EA ENGINEERING SCIENCE AND TECHNOLOGY PBC") -> 9 | E29: =C29/$C$447 -> 0.0085369721
A30: KELLER BROTHERS INC | B30: Other / General | C30: =SUMIF('AP Line Items'!C:C,"KELLER BROTHERS",'AP Line Items'!E:E) -> 96681.5 | D30: =COUNTIF('AP Line Items'!C:C,"KELLER BROTHERS") -> 1 | E30: =C30/$C$447 -> 0.0083070814
A31: BECKER MORGAN GROUP INC | B31: Other / General | C31: =SUMIF('AP Line Items'!C:C,"BECKER MORGAN GROUP",'AP Line Items'!E:E) -> 95485.87 | D31: =COUNTIF('AP Line Items'!C:C,"BECKER MORGAN GROUP") -> 9 | E31: =C31/$C$447 -> 0.0082043503
A32: TECHMD | B32: Technology & Software | C32: =SUMIF('AP Line Items'!C:C,"TECHMD",'AP Line Items'!E:E) -> 90473.98 | D32: =COUNTIF('AP Line Items'!C:C,"TECHMD") -> 24 | E32: =C32/$C$447 -> 0.007773718
A33: LINDSAY FORD LLC | B33: Vehicles, Fleet & Equipment | C33: =SUMIF('AP Line Items'!C:C,"LINDSAY FORD",'AP Line Items'!E:E) -> 89674 | D33: =COUNTIF('AP Line Items'!C:C,"LINDSAY FORD") -> 1 | E33: =C33/$C$447 -> 0.007704982
A34: PIGG, KRAHL, STERN & CO., P.A. | B34: Professional Services (Legal/Eng/Audit) | C34: =SUMIF('AP Line Items'!C:C,"PIGG KRAHL STERN & PA",'AP Line Items'!E:E) -> 82900 | D34: =COUNTIF('AP Line Items'!C:C,"PIGG KRAHL STERN & PA") -> 3 | E34: =C34/$C$447 -> 0.0071229454
A35: BENNETT CONSTRUCTION, INC | B35: Construction & Infrastructure | C35: =SUMIF('AP Line Items'!C:C,"BENNETT CONSTRUCTION",'AP Line Items'!E:E) -> 72684.9 | D35: =COUNTIF('AP Line Items'!C:C,"BENNETT CONSTRUCTION") -> 1 | E35: =C35/$C$447 -> 0.0062452422
A36: AC SCHULTES OF DELAWARE INC | B36: Construction & Infrastructure | C36: =SUMIF('AP Line Items'!C:C,"AC SCHULTES OF DELAWARE",'AP Line Items'!E:E) -> 71960 | D36: =COUNTIF('AP Line Items'!C:C,"AC SCHULTES OF DELAWARE") -> 3 | E36: =C36/$C$447 -> 0.0061829572
A37: DEERE & COMPANY | B37: Other / General | C37: =SUMIF('AP Line Items'!C:C,"DEERE & COMPANY",'AP Line Items'!E:E) -> 67938.76 | D37: =COUNTIF('AP Line Items'!C:C,"DEERE & COMPANY") -> 1 | E37: =C37/$C$447 -> 0.0058374436
A38: FREEMIRE & ASSOCIATES | B38: Professional Services (Legal/Eng/Audit) | C38: =SUMIF('AP Line Items'!C:C,"FREEMIRE & ASSOCIATES",'AP Line Items'!E:E) -> 67451.82 | D38: =COUNTIF('AP Line Items'!C:C,"FREEMIRE & ASSOCIATES") -> 6 | E38: =C38/$C$447 -> 0.0057956047
A39: AT&T MOBILITY | B39: Utilities & Telecom | C39: =SUMIF('AP Line Items'!C:C,"AT&T MOBILITY",'AP Line Items'!E:E) -> 65730.7 | D39: =COUNTIF('AP Line Items'!C:C,"AT&T MOBILITY") -> 13 | E39: =C39/$C$447 -> 0.0056477224
A40: EAST COAST UNDERGROUND | B40: Construction & Infrastructure | C40: =SUMIF('AP Line Items'!C:C,"EAST COAST UNDERGROUND",'AP Line Items'!E:E) -> 63814.12 | D40: =COUNTIF('AP Line Items'!C:C,"EAST COAST UNDERGROUND") -> 1 | E40: =C40/$C$447 -> 0.0054830458
...

Sheet AP Line Items
A1: Meeting Date | B1: Vendor (as printed) | C1: Vendor (normalized) | D1: Category | E1: Amount | F1: Description
A2: 01.27.2025 | B2: 1NTEGER/TECHMD/ICS | C2: 1NTEGER/TECHMD/ICS | D2: Technology & Software | E2: 880 | F2: 1NTEGER CORE SECURITY
A3: 01.27.2025 | B3: ABC PRINTERS INC | C3: ABC PRINTERS | D3: Printing & Office | E3: 60 | F3: ADDTL 2025 DESK CALENDARS
A4: 01.27.2025 | B4: AC SCHULTES OF DELAWARE INC | C4: AC SCHULTES OF DELAWARE | D4: Construction & Infrastructure | E4: 2800 | F4: PLUGGING THE CELLAR WELL #2
A5: 01.27.2025 | B5: ADVANCE AUTO PARTS | C5: ADVANCE AUTO PARTS | D5: Vehicles, Fleet & Equipment | E5: 43.98 | F5: REPLACEMENT HEADLIGHTS FOR VEHICLE #74 F-450
A6: 01.27.2025 | B6: ALTEC INDUSTRIES INC | C6: ALTEC INDUSTRIES | D6: Vehicles, Fleet & Equipment | E6: 133.31 | F6: BEACON LIGHT LED AMBER BLACKOUT LENS (VEH.# 3)
A7: 01.27.2025 | B7: ANIXTER POWER SOLUTIONS, LLC | C7: ANIXTER POWER SOLUTIONS | D7: Electric/Water Utility Materials | E7: 918 | F7: GE CURRENT TRANSFORMERS JAK-OC-400:5 STYLE
A8: 01.27.2025 | B8: AQUALAW PLC | C8: AQUALAW | D8: Professional Services (Legal/Eng/Audit) | E8: 4884 | F8: REVIEW DISCHARGE PERMIT
A9: 01.27.2025 | B9: AT&T MOBILITY | C9: AT&T MOBILITY | D9: Utilities & Telecom | E9: 4073.73 | F9: DEC FY 25 AT&T MOBILITY TOWN ISSUED DEVICES NOV 2024
A10: 01.27.2025 | B10: ATLANTIC MACHINERY, INC | C10: ATLANTIC MACHINERY | D10: Vehicles, Fleet & Equipment | E10: 1802.97 | F10: ENZ NOZZLES JETVAC
A11: 01.27.2025 | B11: CARTER MACHINERY COMPANY INC | C11: CARTER MACHINERY COMPANY | D11: Vehicles, Fleet & Equipment | E11: 5600 | F11: G3520 PM MAINTENANCE POWER PLANT
A12: 01.27.2025 | B12: CATO OIL CO., INC. | C12: CATO OIL | D12: Other / General | E12: 9846.96 | F12: TOWN VEHICLE GAS
A13: 01.27.2025 | B13: CHOPTANK ELECTRIC COOPERATIVE, INC. | C13: CHOPTANK ELECTRIC COOPERATIVE | D13: Other / General | E13: 3769.32 | F13: DEC FY 25 ELECTRIC UTILITY SERVICE SPRAY SITE
... A1812: 06.08.2026 | B1812: WORCESTER COUNTY LANDFILL | C1812: WORCESTER COUNTY LANDFILL | D1812: Waste & Disposal | E1812: 13466 | F1812: MAY FY 26 REFUSE RECYCLE CAN PULLS AND DEMOLITIONS / MAY FY 26 SLUDGE DISPOSAL
D1814: TOTAL | E1814: =SUM(E2:E1812) -> 11638444

Sheet Utility Refunds
A1: Meeting Date | B1: Payee | C1: Check # | D1: Amount
A2: 01.27.2025 | B2: DITTERT, ROBERT | C2: 28090 | D2: 114.69
A3: 01.27.2025 | B3: PORTILLO, BERNABE | C3: 28089 | D3: 180.26
A4: 01.27.2025 | B4: REYNOLDS, ALAN | C4: 28088 | D4: 13.19
A5: 01.27.2025 | B5: RIEHL, SOPHIA | C5: 28087 | D5: 221.18
A6: 01.27.2025 | B6: HUDSON, JAMES | C6: 28085 | D6: 41.1
A7: 01.27.2025 | B7: INC, HORTON | C7: 28086 | D7: 168.78
A8: 01.27.2025 | B8: SHORE UP-REFUNDS | C8: 28158 | D8: 63.02
A9: 01.27.2025 | B9: SHORE UP-REFUNDS | C9: 28157 | D9: 697.59
A10: 01.27.2025 | B10: JOSEPH, CHERY | C10: 28204 | D10: 108.54
A11: 01.27.2025 | B11: POP, EUGENIO | C11: 28203 | D11: 2.62
A12: 02.24.2025 | B12: ROBERTSON, CHRISTIAN | C12: 28314 | D12: 136.54
A13: 03.10.2025 | B13: GLAUB, JOSHUA | C13: 28422 | D13: 113.99
... A76: 06.08.2026 | B76: WILLIAMS, MELISSA | C76: 31106 | D76: 86.98
C78: TOTAL | D78: =SUM(D2:D76) -> 28550.47

Sheet Credit Cards (memo)
A1: Meeting Date | B1: Cardholder / Account | C1: New Balance
A2: 01.27.2025 | B2: BANK OF OCEAN CITY (account XXXX XXXX XXXX - unidentified) | C2: 1314.83
A3: 01.27.2025 | B3: BANK OF OCEAN CITY (account XXXX XXXX XXXX - unidentified) | C3: 1276.07
A4: 01.27.2025 | B4: BANK OF OCEAN CITY (account XXXX XXXX XXXX - unidentified) | C4: 1027.38
A5: 01.27.2025 | B5: BANK OF OCEAN CITY (account XXXX XXXX XXXX - unidentified) | C5: 470.4
A6: 01.27.2025 | B6: BANK OF OCEAN CITY (account XXXX XXXX XXXX - unidentified) | C6: 40.17
A7: 01.27.2025 | B7: BANK OF OCEAN CITY (account XXXX XXXX XXXX - unidentified) | C7: 1259.62
A8: 01.27.2025 | B8: BANK OF OCEAN CITY (account XXXX XXXX XXXX - unidentified) | C8: 468.35
A9: 01.27.2025 | B9: BANK OF OCEAN CITY (account XXXX XXXX XXXX - unidentified) | C9: 753.87
A10: 01.27.2025 | B10: BANK OF OCEAN CITY (account XXXX XXXX XXXX - unidentified) | C10: 920.31
A11: 01.27.2025 | B11: BANK OF OCEAN CITY (account XXXX XXXX XXXX - unidentified) | C11: 1891.43
A12: 01.27.2025 | B12: BANK OF OCEAN CITY (account XXXX XXXX XXXX - unidentified) | C12: 3740
A13: 01.27.2025 | B13: BANK OF OCEAN CITY (account XXXX XXXX XXXX - unidentified) | C13: 1218.69
... A168: 06.08.2026 | B168: BANK OF OCEAN CITY - Card 15 (XXXX XXXX XXXX) Credit Limit $5000 Statement Closing 05/10/2026 | C168: 633.04
B170: TOTAL (memo only - NOT in grand total) | C170: =SUM(C2:C168) -> 165073.46
